<sdf version='1.7'>
  <world name='default'>
    <light name='sun' type='directional'>
      <cast_shadows>1</cast_shadows>
      <pose>0 0 10 0 -0 0</pose>
      <diffuse>0.8 0.8 0.8 1</diffuse>
      <specular>0.2 0.2 0.2 1</specular>
      <attenuation>
        <range>1000</range>
        <constant>0.9</constant>
        <linear>0.01</linear>
        <quadratic>0.001</quadratic>
      </attenuation>
      <direction>-0.5 0.1 -0.9</direction>
      <spot>
        <inner_angle>0</inner_angle>
        <outer_angle>0</outer_angle>
        <falloff>0</falloff>
      </spot>
    </light>
    <model name='ground_plane'>
      <static>1</static>
      <link name='link'>
        <collision name='collision'>
          <geometry>
            <plane>
              <normal>0 0 1</normal>
              <size>100 100</size>
            </plane>
          </geometry>
          <surface>
            <friction>
              <ode>
                <mu>100</mu>
                <mu2>50</mu2>
              </ode>
              <torsional>
                <ode/>
              </torsional>
            </friction>
            <contact>
              <ode/>
            </contact>
            <bounce/>
          </surface>
          <max_contacts>10</max_contacts>
        </collision>
        <visual name='visual'>
          <cast_shadows>0</cast_shadows>
          <geometry>
            <plane>
              <normal>0 0 1</normal>
              <size>100 100</size>
            </plane>
          </geometry>
          <material>
            <script>
              <uri>file://media/materials/scripts/gazebo.material</uri>
              <name>Gazebo/Grey</name>
            </script>
          </material>
        </visual>
        <self_collide>0</self_collide>
        <enable_wind>0</enable_wind>
        <kinematic>0</kinematic>
      </link>
    </model>
    <gravity>0 0 -9.8</gravity>
    <magnetic_field>6e-06 2.3e-05 -4.2e-05</magnetic_field>
    <atmosphere type='adiabatic'/>
    <physics type='ode'>
      <max_step_size>0.001</max_step_size>
      <real_time_factor>1</real_time_factor>
      <real_time_update_rate>1000</real_time_update_rate>
    </physics>
    <scene>
      <ambient>0.4 0.4 0.4 1</ambient>
      <background>0.7 0.7 0.7 1</background>
      <shadows>1</shadows>
    </scene>
    <wind/>
    <spherical_coordinates>
      <surface_model>EARTH_WGS84</surface_model>
      <latitude_deg>0</latitude_deg>
      <longitude_deg>0</longitude_deg>
      <elevation>0</elevation>
      <heading_deg>0</heading_deg>
    </spherical_coordinates>
    <model name='iscas_museum'>
      <link name='link'>
        <inertial>
          <mass>15</mass>
        </inertial>
        <collision name='collision'>
          <pose>0 0 0 0 0 -1.57</pose>
          <geometry>
            <mesh>
              <uri>model://iscas_museum/meshes/ISCAS_museum.dae</uri>
            </mesh>
          </geometry>
          <max_contacts>10</max_contacts>
          <surface>
            <contact>
              <ode/>
            </contact>
            <bounce/>
            <friction>
              <torsional>
                <ode/>
              </torsional>
              <ode/>
            </friction>
          </surface>
        </collision>
        <visual name='visual'>
          <pose>0 0 0 0 0 -1.57</pose>
          <geometry>
            <mesh>
              <uri>model://iscas_museum/meshes/ISCAS_museum.dae</uri>
            </mesh>
          </geometry>
        </visual>
        <self_collide>0</self_collide>
        <enable_wind>0</enable_wind>
        <kinematic>0</kinematic>
      </link>
      <static>1</static>
      <pose>-0.296044 0.662336 0 0 -0 0</pose>
    </model>
    <state world_name='default'>
      <sim_time>570 152000000</sim_time>
      <real_time>345 638243981</real_time>
      <wall_time>1736611006 646387396</wall_time>
      <iterations>201495</iterations>
      <model name='Construction Barrel'>
        <pose>0.304028 8.91686 -4e-06 -3e-06 -1e-05 -1.2e-05</pose>
        <scale>1 1 1</scale>
        <link name='link'>
          <pose>0.304028 8.91686 -4e-06 -3e-06 -1e-05 -1.2e-05</pose>
          <velocity>0 0 0 0 -0 0</velocity>
          <acceleration>-2.29275 0.112775 -5.75761 2.29564 0.00677 -2.02192</acceleration>
          <wrench>-1146.37 56.3875 -2878.8 0 -0 0</wrench>
        </link>
      </model>
      <model name='Construction Barrel_0'>
        <pose>4.39833 6.98201 1e-06 3e-06 2e-06 -1.1e-05</pose>
        <scale>1 1 1</scale>
        <link name='link'>
          <pose>4.39833 6.98201 1e-06 3e-06 2e-06 -1.1e-05</pose>
          <velocity>0 0 0 0 -0 0</velocity>
          <acceleration>-0.127578 6.72898 1.66267 2.02059 -0.390903 0.035236</acceleration>
          <wrench>-63.7888 3364.49 831.333 0 -0 0</wrench>
        </link>
      </model>
      <model name='Construction Barrel_1'>
        <pose>-4.23765 -6.6852 0 0 0 -3e-06</pose>
        <scale>1 1 1</scale>
        <link name='link'>
          <pose>-4.23765 -6.6852 0 0 0 -3e-06</pose>
          <velocity>0 0 0 0 -0 0</velocity>
          <acceleration>3.45854 5.74438 4.40609 1.34623 0.77903 3.14097</acceleration>
          <wrench>1729.27 2872.19 2203.04 0 -0 0</wrench>
        </link>
      </model>
      <model name='Construction Cone'>
        <pose>4.2015 -1.42331 -0 0 -0 0</pose>
        <scale>1 1 1</scale>
        <link name='link'>
          <pose>4.2015 -1.42331 -0 0 -0 0</pose>
          <velocity>0 0 0 0 -0 0</velocity>
          <acceleration>0 -0 -0.008512 -2.58585 1.13682 3.14159</acceleration>
          <wrench>0 -0 -0.008512 0 -0 0</wrench>
        </link>
      </model>
      <model name='Construction Cone_0'>
        <pose>-0.239893 -6.59766 -0 0 -0 0</pose>
        <scale>1 1 1</scale>
        <link name='link'>
          <pose>-0.239893 -6.59766 -0 0 -0 0</pose>
          <velocity>0 0 0 0 -0 0</velocity>
          <acceleration>0 -0 -0.008512 -2.58585 1.13682 3.14159</acceleration>
          <wrench>0 -0 -0.008512 0 -0 0</wrench>
        </link>
      </model>
      <model name='Construction Cone_1'>
        <pose>-5.5648 0.238086 -0 0 -1e-06 0</pose>
        <scale>1 1 1</scale>
        <link name='link'>
          <pose>-5.5648 0.238086 -0 0 -1e-06 0</pose>
          <velocity>0 0 0 0 -0 0</velocity>
          <acceleration>-0 0 0.008512 2.58585 -1.13682 -3.14159</acceleration>
          <wrench>-0 0 0.008512 0 -0 0</wrench>
        </link>
      </model>
      <model name='ground_plane'>
        <pose>0 0 0 0 -0 0</pose>
        <scale>1 1 1</scale>
        <link name='link'>
          <pose>0 0 0 0 -0 0</pose>
          <velocity>0 0 0 0 -0 0</velocity>
          <acceleration>0 0 0 0 -0 0</acceleration>
          <wrench>0 0 0 0 -0 0</wrench>
        </link>
      </model>
      <model name='iscas_museum'>
        <pose>-0.296044 0.662336 0 0 -0 0</pose>
        <scale>1 1 1</scale>
        <link name='link'>
          <pose>-0.296044 0.662336 0 0 -0 0</pose>
          <velocity>0 0 0 0 -0 0</velocity>
          <acceleration>0 0 0 0 -0 0</acceleration>
          <wrench>0 0 0 0 -0 0</wrench>
        </link>
      </model>
      <model name='number1'>
        <pose>4.90151 1.71426 0.4 0 -0 0</pose>
        <scale>1 1 1</scale>
        <link name='link'>
          <pose>4.90151 1.71426 0.4 0 -0 0</pose>
          <velocity>0 0 0 0 -0 0</velocity>
          <acceleration>0 0 0 0 -0 0</acceleration>
          <wrench>0 0 0 0 -0 0</wrench>
        </link>
      </model>
      <model name='number2'>
        <pose>-6.65219 -4.42011 0.4 0 -0 0</pose>
        <scale>1 1 1</scale>
        <link name='link'>
          <pose>-6.65219 -4.42011 0.4 0 -0 0</pose>
          <velocity>0 0 0 0 -0 0</velocity>
          <acceleration>0 0 0 0 -0 0</acceleration>
          <wrench>0 0 0 0 -0 0</wrench>
        </link>
      </model>
      <model name='treewheel_mobile'>
        <pose>0.003303 0.000379 0.046173 -0.00037 0.059603 0.012467</pose>
        <scale>1 1 1</scale>
        <link name='base_link'>
          <pose>0.003303 0.000379 0.046173 -0.00037 0.059603 0.012467</pose>
          <velocity>-6e-06 -2e-06 9e-06 2.7e-05 -0.00012 7.9e-05</velocity>
          <acceleration>-0 -0 0 -4.1e-05 0 1e-06</acceleration>
          <wrench>-0 -0 0 0 -0 0</wrench>
        </link>
        <link name='castor'>
          <pose>0.075601 0.001279 0.039354 -0.005301 0.059389 -0.070606</pose>
          <velocity>-6e-06 3e-06 1.8e-05 -8.6e-05 -0.000223 1e-05</velocity>
          <acceleration>-0 0 0 0 -0 0</acceleration>
          <wrench>-0 0 0 0 -0 0</wrench>
        </link>
        <link name='castor_wheel'>
          <pose>0.089113 7.3e-05 0.014505 -0.042728 -1.56471 1.54329</pose>
          <velocity>-7e-06 2e-06 2.8e-05 -0.000116 -0.000472 -4.4e-05</velocity>
          <acceleration>-0 0 0 0 -0 0</acceleration>
          <wrench>-0 0 0 0 -0 0</wrench>
        </link>
        <link name='left_wheel'>
          <pose>-0.031714 0.080193 0.034399 -1.57128 0.085494 0.012447</pose>
          <velocity>-6e-06 -4e-06 9e-06 0.000125 -0.000183 -6e-05</velocity>
          <acceleration>-0 -0 -0 -0.000641 0.051324 9.9e-05</acceleration>
          <wrench>-0 -0 -0 0 -0 0</wrench>
        </link>
        <link name='right_wheel'>
          <pose>-0.029711 -0.080293 0.034458 1.57106 -0.042705 -3.12913</pose>
          <velocity>-0 -4e-06 4e-06 0.000126 -1.6e-05 2.8e-05</velocity>
          <acceleration>-0 -0 -0 0.001026 -0.082252 -8.5e-05</acceleration>
          <wrench>-0 -0 -0 0 -0 0</wrench>
        </link>
      </model>
      <light name='sun'>
        <pose>0 0 10 0 -0 0</pose>
      </light>
    </state>
    <gui fullscreen='0'>
      <camera name='user_camera'>
        <pose>6.15141 -13.8276 11.7036 0 0.439643 2.11619</pose>
        <view_controller>orbit</view_controller>
        <projection_type>perspective</projection_type>
      </camera>
    </gui>
    <audio>
      <device>default</device>
    </audio>
    <model name='treewheel_mobile'>
      <link name='base_link'>
        <inertial>
          <pose>0.008468 -7e-06 -0.004501 0 -0 0</pose>
          <mass>0.1311</mass>
          <inertia>
            <ixx>0.000406585</ixx>
            <ixy>1.52799e-09</ixy>
            <ixz>3.19616e-06</ixz>
            <iyy>0.000619389</iyy>
            <iyz>-1.98846e-09</iyz>
            <izz>0.000512803</izz>
          </inertia>
        </inertial>
        <collision name='base_link_collision'>
          <pose>0 0 0 0 -0 0</pose>
          <geometry>
            <mesh>
              <scale>1 1 1</scale>
              <uri>model://mobile_robot/meshes/base_link.STL</uri>
            </mesh>
          </geometry>
          <surface>
            <contact>
              <ode>
                <kp>1000</kp>
                <kd>10</kd>
              </ode>
            </contact>
            <friction>
              <ode>
                <mu>0.2</mu>
                <mu2>0.2</mu2>
              </ode>
              <torsional>
                <ode/>
              </torsional>
            </friction>
            <bounce/>
          </surface>
          <max_contacts>10</max_contacts>
        </collision>
        <collision name='base_link_fixed_joint_lump__Lidar_link_collision_1'>
          <pose>0 0 0.02 0 -0.087 0</pose>
          <geometry>
            <cylinder>
              <length>0.01</length>
              <radius>0.05</radius>
            </cylinder>
          </geometry>
          <surface>
            <contact>
              <ode/>
            </contact>
            <friction>
              <ode/>
              <torsional>
                <ode/>
              </torsional>
            </friction>
            <bounce/>
          </surface>
          <max_contacts>10</max_contacts>
        </collision>
        <collision name='base_link_fixed_joint_lump__radar_link_collision_2'>
          <pose>-0.1 0 0.002 0 -0 0</pose>
          <geometry>
            <box>
              <size>0.002 0.002 0.002</size>
            </box>
          </geometry>
          <surface>
            <contact>
              <ode/>
            </contact>
            <friction>
              <ode/>
              <torsional>
                <ode/>
              </torsional>
            </friction>
            <bounce/>
          </surface>
          <max_contacts>10</max_contacts>
        </collision>
        <collision name='base_link_fixed_joint_lump__top_structure_collision_3'>
          <pose>0 0 0.005 0 -0 0</pose>
          <geometry>
            <box>
              <size>0.09 0.09 0.01</size>
            </box>
          </geometry>
          <surface>
            <contact>
              <ode>
                <kp>1000</kp>
                <kd>10</kd>
              </ode>
            </contact>
            <friction>
              <ode>
                <mu>0.2</mu>
                <mu2>0.2</mu2>
              </ode>
              <torsional>
                <ode/>
              </torsional>
            </friction>
            <bounce/>
          </surface>
          <max_contacts>10</max_contacts>
        </collision>
        <visual name='base_link_visual'>
          <pose>0 0 0 0 -0 0</pose>
          <geometry>
            <mesh>
              <scale>1 1 1</scale>
              <uri>model://mobile_robot/meshes/base_link.STL</uri>
            </mesh>
          </geometry>
          <material>
            <script>
              <name>Gazebo/Red</name>
              <uri>file://media/materials/scripts/gazebo.material</uri>
            </script>
          </material>
        </visual>
        <visual name='base_link_fixed_joint_lump__Lidar_link_visual_1'>
          <pose>-0.001303 0 0.034943 0 -0.087 0</pose>
          <geometry>
            <cylinder>
              <length>0.01</length>
              <radius>0.05</radius>
            </cylinder>
          </geometry>
        </visual>
        <visual name='base_link_fixed_joint_lump__camera_link_visual_2'>
          <pose>0.085 0 0.029 0 -0.2 0</pose>
          <geometry>
            <box>
              <size>0.002 0.002 0.002</size>
            </box>
          </geometry>
        </visual>
        <visual name='base_link_fixed_joint_lump__radar_link_visual_3'>
          <pose>-0.1 0 0.002 0 -0 0</pose>
          <geometry>
            <box>
              <size>0.002 0.002 0.002</size>
            </box>
          </geometry>
        </visual>
        <visual name='base_link_fixed_joint_lump__top_structure_visual_4'>
          <pose>0.01 0 0.013 0 -0 0</pose>
          <geometry>
            <box>
              <size>0.151 0.0999 0.03</size>
            </box>
          </geometry>
          <material>
            <script>
              <name>Gazebo/Red</name>
              <uri>file://media/materials/scripts/gazebo.material</uri>
            </script>
          </material>
        </visual>
        <sensor name='lidar' type='ray'>
          <always_on>1</always_on>
          <visualize>1</visualize>
          <update_rate>20</update_rate>
          <ray>
            <scan>
              <horizontal>
                <samples>120</samples>
                <resolution>1</resolution>
                <min_angle>-1.047</min_angle>
                <max_angle>1.047</max_angle>
              </horizontal>
              <vertical>
                <samples>1</samples>
                <min_angle>0</min_angle>
                <max_angle>0</max_angle>
              </vertical>
            </scan>
            <range>
              <min>0.07</min>
              <max>5</max>
              <resolution>0.015</resolution>
            </range>
            <noise>
              <type>gaussian</type>
              <mean>0</mean>
              <stddev>0.01</stddev>
            </noise>
          </ray>
          <plugin name='scan' filename='libgazebo_ros_ray_sensor.so'>
            <ros>
              <remapping>~/out:=laser_scan</remapping>
            </ros>
            <output_type>sensor_msgs/LaserScan</output_type>
            <frame_name>Lidar_link</frame_name>
          </plugin>
          <pose>0 0 0.02 0 -0.087 0</pose>
        </sensor>
        <sensor name='camera' type='camera'>
          <update_rate>30</update_rate>
          <camera>
            <horizontal_fov>1.047</horizontal_fov>
            <image>
              <width>640</width>
              <height>480</height>
              <format>R8G8B8</format>
            </image>
            <clip>
              <near>0.1</near>
              <far>100</far>
            </clip>
          </camera>
          <plugin name='camera_controller' filename='libgazebo_ros_camera.so'>
            <ros>
              <namespace>/treewheel_mobile</namespace>
              <argument>image_raw</argument>
            </ros>
          </plugin>
          <visualize>1</visualize>
          <pose>0.085 0 0.029 0 -0.2 0</pose>
        </sensor>
        <gravity>1</gravity>
        <sensor name='imu_sensor' type='imu'>
          <always_on>1</always_on>
          <update_rate>100</update_rate>
          <visualize>1</visualize>
          <topic>imu_data</topic>
          <imu>
            <angular_velocity>
              <noise>
                <type>gaussian</type>
                <mean>0.0</mean>
                <stddev>0.01</stddev>
              </noise>
            </angular_velocity>
            <linear_acceleration>
              <noise>
                <type>gaussian</type>
                <mean>0.0</mean>
                <stddev>0.02</stddev>
              </noise>
            </linear_acceleration>
          </imu>
          <pose>0 0 0 0 -0 0</pose>
        </sensor>
        <sensor name='radar_sensor' type='ray'>
          <ray>
            <scan>
              <horizontal>
                <samples>512</samples>
                <resolution>1</resolution>
                <min_angle>-0.785398</min_angle>
                <max_angle>0.785398</max_angle>
              </horizontal>
              <vertical>
                <samples>1</samples>
                <min_angle>0</min_angle>
                <max_angle>0</max_angle>
              </vertical>
            </scan>
            <range>
              <min>0.1</min>
              <max>10</max>
              <resolution>0.01</resolution>
            </range>
            <update_rate>30</update_rate>
            <always_on>1</always_on>
            <visualize>1</visualize>
          </ray>
          <plugin name='gazebo_ros_ray_sensor' filename='libgazebo_ros_ray_sensor.so'>
            <robotNamespace>/robot</robotNamespace>
            <remapping>~/out:=/radar_scan</remapping>
            <frameName>radar_link</frameName>
          </plugin>
          <pose>-0.1 0 0.002 0 -0 0</pose>
        </sensor>
        <self_collide>0</self_collide>
        <enable_wind>0</enable_wind>
        <kinematic>0</kinematic>
      </link>
      <joint name='castorjoint' type='revolute'>
        <pose relative_to='base_link'>0.072581 0 -0.0025 0 -0 0</pose>
        <parent>base_link</parent>
        <child>castor</child>
        <axis>
          <xyz>0 0 1</xyz>
          <limit>
            <lower>-1e+16</lower>
            <upper>1e+16</upper>
          </limit>
          <dynamics>
            <spring_reference>0</spring_reference>
            <spring_stiffness>0</spring_stiffness>
          </dynamics>
        </axis>
      </joint>
      <link name='castor'>
        <pose relative_to='castorjoint'>0 0 0 0 -0 0</pose>
        <inertial>
          <pose>0.001714 -8e-06 -0.005015 0 -0 0</pose>
          <mass>0.5</mass>
          <inertia>
            <ixx>4e-05</ixx>
            <ixy>0</ixy>
            <ixz>0</ixz>
            <iyy>4e-05</iyy>
            <iyz>0</iyz>
            <izz>1e-05</izz>
          </inertia>
        </inertial>
        <collision name='castor_collision'>
          <pose>0 0 0 0 -0 0</pose>
          <geometry>
            <mesh>
              <scale>1 1 1</scale>
              <uri>model://mobile_robot/meshes/castor.STL</uri>
            </mesh>
          </geometry>
          <surface>
            <contact>
              <ode>
                <kp>1e+06</kp>
                <kd>1</kd>
              </ode>
            </contact>
            <friction>
              <ode>
                <mu>0.1</mu>
                <mu2>0.1</mu2>
              </ode>
              <torsional>
                <ode/>
              </torsional>
            </friction>
            <bounce/>
          </surface>
          <max_contacts>10</max_contacts>
        </collision>
        <visual name='castor_visual'>
          <pose>0 0 0 0 -0 0</pose>
          <geometry>
            <mesh>
              <scale>1 1 1</scale>
              <uri>model://mobile_robot/meshes/castor.STL</uri>
            </mesh>
          </geometry>
          <material>
            <script>
              <name>Gazebo/Gray</name>
              <uri>file://media/materials/scripts/gazebo.material</uri>
            </script>
          </material>
        </visual>
        <self_collide>0</self_collide>
        <enable_wind>0</enable_wind>
        <kinematic>0</kinematic>
      </link>
      <joint name='castor_wheel_joint' type='revolute'>
        <pose relative_to='castor'>0.015014 -0.000123 -0.024 0 -1.57 1.5708</pose>
        <parent>castor</parent>
        <child>castor_wheel</child>
        <axis>
          <xyz>0 0 1</xyz>
          <limit>
            <lower>-1e+16</lower>
            <upper>1e+16</upper>
          </limit>
          <dynamics>
            <spring_reference>0</spring_reference>
            <spring_stiffness>0</spring_stiffness>
          </dynamics>
        </axis>
      </joint>
      <link name='castor_wheel'>
        <pose relative_to='castor_wheel_joint'>0 0 0 0 -0 0</pose>
        <inertial>
          <pose>0 -0 -0 0 -0 0</pose>
          <mass>0.082874</mass>
          <inertia>
            <ixx>0.0004</ixx>
            <ixy>0</ixy>
            <ixz>0</ixz>
            <iyy>0.0004</iyy>
            <iyz>0</iyz>
            <izz>1e-05</izz>
          </inertia>
        </inertial>
        <collision name='castor_wheel_collision'>
          <pose>0 0 0 0 -0 0</pose>
          <geometry>
            <mesh>
              <scale>1 1 1</scale>
              <uri>model://mobile_robot/meshes/castor_wheel.STL</uri>
            </mesh>
          </geometry>
          <surface>
            <contact>
              <ode>
                <kp>1e+06</kp>
                <kd>1</kd>
              </ode>
            </contact>
            <friction>
              <ode>
                <mu>0.1</mu>
                <mu2>0.1</mu2>
              </ode>
              <torsional>
                <ode/>
              </torsional>
            </friction>
            <bounce/>
          </surface>
          <max_contacts>10</max_contacts>
        </collision>
        <visual name='castor_wheel_visual'>
          <pose>0 0 0 0 -0 0</pose>
          <geometry>
            <mesh>
              <scale>1 1 1</scale>
              <uri>model://mobile_robot/meshes/castor_wheel.STL</uri>
            </mesh>
          </geometry>
          <material>
            <script>
              <name>Gazebo/Gray</name>
              <uri>file://media/materials/scripts/gazebo.material</uri>
            </script>
          </material>
        </visual>
        <self_collide>0</self_collide>
        <enable_wind>0</enable_wind>
        <kinematic>0</kinematic>
      </link>
      <joint name='leftwheel' type='revolute'>
        <pose relative_to='base_link'>-0.033259 0.08025 -0.01375 -1.5708 0.042481 0</pose>
        <parent>base_link</parent>
        <child>left_wheel</child>
        <axis>
          <xyz>0 0 1</xyz>
          <limit>
            <lower>-1e+16</lower>
            <upper>1e+16</upper>
          </limit>
          <dynamics>
            <damping>0.1</damping>
            <friction>0.1</friction>
            <spring_reference>0</spring_reference>
            <spring_stiffness>0</spring_stiffness>
          </dynamics>
        </axis>
      </joint>
      <link name='left_wheel'>
        <pose relative_to='leftwheel'>0 0 0 0 -0 0</pose>
        <inertial>
          <pose>0 -0 -0.011873 0 -0 0</pose>
          <mass>0.1403</mass>
          <inertia>
            <ixx>2e-05</ixx>
            <ixy>0</ixy>
            <ixz>0</ixz>
            <iyy>2e-05</iyy>
            <iyz>0</iyz>
            <izz>0.0001</izz>
          </inertia>
        </inertial>
        <collision name='left_wheel_collision'>
          <pose>0 0 0 0 -0 0</pose>
          <geometry>
            <mesh>
              <scale>1 1 1</scale>
              <uri>model://mobile_robot/meshes/left_wheel.STL</uri>
            </mesh>
          </geometry>
          <surface>
            <contact>
              <ode>
                <kp>1e+06</kp>
                <kd>1</kd>
              </ode>
            </contact>
            <friction>
              <ode>
                <mu>200</mu>
                <mu2>200</mu2>
              </ode>
              <torsional>
                <ode/>
              </torsional>
            </friction>
            <bounce/>
          </surface>
          <max_contacts>10</max_contacts>
        </collision>
        <visual name='left_wheel_visual'>
          <pose>0 0 0 0 -0 0</pose>
          <geometry>
            <mesh>
              <scale>1 1 1</scale>
              <uri>model://mobile_robot/meshes/left_wheel.STL</uri>
            </mesh>
          </geometry>
          <material>
            <script>
              <name>Gazebo/Gray</name>
              <uri>file://media/materials/scripts/gazebo.material</uri>
            </script>
          </material>
        </visual>
        <self_collide>0</self_collide>
        <enable_wind>0</enable_wind>
        <kinematic>0</kinematic>
      </link>
      <joint name='rightwheel' type='revolute'>
        <pose relative_to='base_link'>-0.033259 -0.08025 -0.01375 1.5708 0.042481 3.14159</pose>
        <parent>base_link</parent>
        <child>right_wheel</child>
        <axis>
          <xyz>0 0 1</xyz>
          <limit>
            <lower>-1e+16</lower>
            <upper>1e+16</upper>
          </limit>
          <dynamics>
            <damping>0.1</damping>
            <friction>0.1</friction>
            <spring_reference>0</spring_reference>
            <spring_stiffness>0</spring_stiffness>
          </dynamics>
        </axis>
      </joint>
      <link name='right_wheel'>
        <pose relative_to='rightwheel'>0 0 0 0 -0 0</pose>
        <inertial>
          <pose>-0 -0 0.011873 0 -0 0</pose>
          <mass>0.1403</mass>
          <inertia>
            <ixx>2e-05</ixx>
            <ixy>0</ixy>
            <ixz>0</ixz>
            <iyy>2e-05</iyy>
            <iyz>0</iyz>
            <izz>0.0001</izz>
          </inertia>
        </inertial>
        <collision name='right_wheel_collision'>
          <pose>0 0 0 0 -0 0</pose>
          <geometry>
            <mesh>
              <scale>1 1 1</scale>
              <uri>model://mobile_robot/meshes/right_wheel.STL</uri>
            </mesh>
          </geometry>
          <surface>
            <contact>
              <ode>
                <kp>1e+06</kp>
                <kd>1</kd>
              </ode>
            </contact>
            <friction>
              <ode>
                <mu>200</mu>
                <mu2>200</mu2>
              </ode>
              <torsional>
                <ode/>
              </torsional>
            </friction>
            <bounce/>
          </surface>
          <max_contacts>10</max_contacts>
        </collision>
        <visual name='right_wheel_visual'>
          <pose>0 0 0 0 -0 0</pose>
          <geometry>
            <mesh>
              <scale>1 1 1</scale>
              <uri>model://mobile_robot/meshes/right_wheel.STL</uri>
            </mesh>
          </geometry>
          <material>
            <script>
              <name>Gazebo/Gray</name>
              <uri>file://media/materials/scripts/gazebo.material</uri>
            </script>
          </material>
        </visual>
        <self_collide>0</self_collide>
        <enable_wind>0</enable_wind>
        <kinematic>0</kinematic>
      </link>
      <plugin name='two_wheeled_robot_diff_drive' filename='libgazebo_ros_diff_drive.so'>
        <update_rate>100</update_rate>
        <left_joint>leftwheel</left_joint>
        <right_joint>rightwheel</right_joint>
        <wheel_separation>0.15</wheel_separation>
        <wheel_diameter>0.06</wheel_diameter>
        <max_wheel_torque>20</max_wheel_torque>
        <max_wheel_acceleration>20.0</max_wheel_acceleration>
        <command_topic>cmd_vel</command_topic>
        <publish_odom>1</publish_odom>
        <publish_odom_tf>1</publish_odom_tf>
        <publish_wheel_tf>1</publish_wheel_tf>
        <odometry_topic>odom</odometry_topic>
        <odometry_frame>odom_link</odometry_frame>
        <robot_base_frame>base_link</robot_base_frame>
        <odometry_source>1</odometry_source>
        <ros>
          <remapping>odom:=wheel/odometry</remapping>
        </ros>
      </plugin>
      <static>0</static>
      <plugin name='gazebo_ros_joint_state_publisher' filename='libgazebo_ros_joint_state_publisher.so'>
        <update_rate>100</update_rate>
        <joint_name>castorjoint</joint_name>
        <joint_name>castor_wheel_joint</joint_name>
      </plugin>
      <pose>0 0 0.05 0 -0 0</pose>
    </model>
    <model name='number1'>
      <pose>4.90151 1.71426 0.4 0 -0 0</pose>
      <static>1</static>
      <link name='link'>
        <visual name='visual'>
          <geometry>
            <mesh>
              <uri>model://number1/meshes/number.dae</uri>
            </mesh>
          </geometry>
          <material>
            <script>
              <uri>model://number1/materials/scripts</uri>
              <uri>model://number1/materials/textures</uri>
              <name>Number/One</name>
            </script>
          </material>
        </visual>
        <self_collide>0</self_collide>
        <enable_wind>0</enable_wind>
        <kinematic>0</kinematic>
      </link>
    </model>
    <model name='Construction Cone'>
      <link name='link'>
        <collision name='collision'>
          <geometry>
            <mesh>
              <scale>10 10 10</scale>
              <uri>model://construction_cone/meshes/construction_cone.dae</uri>
            </mesh>
          </geometry>
          <max_contacts>10</max_contacts>
          <surface>
            <contact>
              <ode/>
            </contact>
            <bounce/>
            <friction>
              <torsional>
                <ode/>
              </torsional>
              <ode/>
            </friction>
          </surface>
        </collision>
        <visual name='visual'>
          <geometry>
            <mesh>
              <scale>10 10 10</scale>
              <uri>model://construction_cone/meshes/construction_cone.dae</uri>
            </mesh>
          </geometry>
        </visual>
        <self_collide>0</self_collide>
        <inertial>
          <pose>0 0 0 0 -0 0</pose>
          <inertia>
            <ixx>1</ixx>
            <ixy>0</ixy>
            <ixz>0</ixz>
            <iyy>1</iyy>
            <iyz>0</iyz>
            <izz>1</izz>
          </inertia>
          <mass>1</mass>
        </inertial>
        <enable_wind>0</enable_wind>
        <kinematic>0</kinematic>
      </link>
      <pose>4.2015 -1.42331 0 0 -0 0</pose>
    </model>
    <model name='Construction Barrel'>
      <link name='link'>
        <inertial>
          <pose>0 0 0.4 0 -0 0</pose>
          <mass>500</mass>
          <inertia>
            <ixx>51.2096</ixx>
            <iyy>51.2096</iyy>
            <izz>25</izz>
            <ixy>0</ixy>
            <ixz>0</ixz>
            <iyz>0</iyz>
          </inertia>
        </inertial>
        <collision name='collision'>
          <geometry>
            <mesh>
              <uri>model://construction_barrel/meshes/construction_barrel.dae</uri>
            </mesh>
          </geometry>
          <max_contacts>10</max_contacts>
          <surface>
            <contact>
              <ode/>
            </contact>
            <bounce/>
            <friction>
              <torsional>
                <ode/>
              </torsional>
              <ode/>
            </friction>
          </surface>
        </collision>
        <visual name='visual'>
          <geometry>
            <mesh>
              <uri>model://construction_barrel/meshes/construction_barrel.dae</uri>
            </mesh>
          </geometry>
        </visual>
        <self_collide>0</self_collide>
        <enable_wind>0</enable_wind>
        <kinematic>0</kinematic>
      </link>
      <pose>0.304085 8.91688 0 0 -0 0</pose>
    </model>
    <model name='Construction Barrel_0'>
      <link name='link'>
        <inertial>
          <pose>0 0 0.4 0 -0 0</pose>
          <mass>500</mass>
          <inertia>
            <ixx>51.2096</ixx>
            <iyy>51.2096</iyy>
            <izz>25</izz>
            <ixy>0</ixy>
            <ixz>0</ixz>
            <iyz>0</iyz>
          </inertia>
        </inertial>
        <collision name='collision'>
          <geometry>
            <mesh>
              <uri>model://construction_barrel/meshes/construction_barrel.dae</uri>
            </mesh>
          </geometry>
          <max_contacts>10</max_contacts>
          <surface>
            <contact>
              <ode/>
            </contact>
            <bounce/>
            <friction>
              <torsional>
                <ode/>
              </torsional>
              <ode/>
            </friction>
          </surface>
        </collision>
        <visual name='visual'>
          <geometry>
            <mesh>
              <uri>model://construction_barrel/meshes/construction_barrel.dae</uri>
            </mesh>
          </geometry>
        </visual>
        <self_collide>0</self_collide>
        <enable_wind>0</enable_wind>
        <kinematic>0</kinematic>
      </link>
      <pose>4.39837 6.98203 0 0 -0 0</pose>
    </model>
    <model name='Construction Cone_0'>
      <link name='link'>
        <collision name='collision'>
          <geometry>
            <mesh>
              <scale>10 10 10</scale>
              <uri>model://construction_cone/meshes/construction_cone.dae</uri>
            </mesh>
          </geometry>
          <max_contacts>10</max_contacts>
          <surface>
            <contact>
              <ode/>
            </contact>
            <bounce/>
            <friction>
              <torsional>
                <ode/>
              </torsional>
              <ode/>
            </friction>
          </surface>
        </collision>
        <visual name='visual'>
          <geometry>
            <mesh>
              <scale>10 10 10</scale>
              <uri>model://construction_cone/meshes/construction_cone.dae</uri>
            </mesh>
          </geometry>
        </visual>
        <self_collide>0</self_collide>
        <inertial>
          <pose>0 0 0 0 -0 0</pose>
          <inertia>
            <ixx>1</ixx>
            <ixy>0</ixy>
            <ixz>0</ixz>
            <iyy>1</iyy>
            <iyz>0</iyz>
            <izz>1</izz>
          </inertia>
          <mass>1</mass>
        </inertial>
        <enable_wind>0</enable_wind>
        <kinematic>0</kinematic>
      </link>
      <pose>-0.239893 -6.59766 0 0 -0 0</pose>
    </model>
    <model name='number2'>
      <pose>-6.65219 -4.42011 0.4 0 -0 0</pose>
      <static>1</static>
      <link name='link'>
        <visual name='visual'>
          <geometry>
            <mesh>
              <uri>model://number1/meshes/number.dae</uri>
            </mesh>
          </geometry>
          <material>
            <script>
              <uri>model://number2/materials/scripts</uri>
              <uri>model://number2/materials/textures</uri>
              <name>Number/Two</name>
            </script>
          </material>
        </visual>
        <self_collide>0</self_collide>
        <enable_wind>0</enable_wind>
        <kinematic>0</kinematic>
      </link>
    </model>
    <model name='Construction Barrel_1'>
      <link name='link'>
        <inertial>
          <pose>0 0 0.4 0 -0 0</pose>
          <mass>500</mass>
          <inertia>
            <ixx>51.2096</ixx>
            <iyy>51.2096</iyy>
            <izz>25</izz>
            <ixy>0</ixy>
            <ixz>0</ixz>
            <iyz>0</iyz>
          </inertia>
        </inertial>
        <collision name='collision'>
          <geometry>
            <mesh>
              <uri>model://construction_barrel/meshes/construction_barrel.dae</uri>
            </mesh>
          </geometry>
          <max_contacts>10</max_contacts>
          <surface>
            <contact>
              <ode/>
            </contact>
            <bounce/>
            <friction>
              <torsional>
                <ode/>
              </torsional>
              <ode/>
            </friction>
          </surface>
        </collision>
        <visual name='visual'>
          <geometry>
            <mesh>
              <uri>model://construction_barrel/meshes/construction_barrel.dae</uri>
            </mesh>
          </geometry>
        </visual>
        <self_collide>0</self_collide>
        <enable_wind>0</enable_wind>
        <kinematic>0</kinematic>
      </link>
      <pose>-4.23764 -6.6852 0 0 -0 0</pose>
    </model>
    <model name='Construction Cone_1'>
      <link name='link'>
        <collision name='collision'>
          <geometry>
            <mesh>
              <scale>10 10 10</scale>
              <uri>model://construction_cone/meshes/construction_cone.dae</uri>
            </mesh>
          </geometry>
          <max_contacts>10</max_contacts>
          <surface>
            <contact>
              <ode/>
            </contact>
            <bounce/>
            <friction>
              <torsional>
                <ode/>
              </torsional>
              <ode/>
            </friction>
          </surface>
        </collision>
        <visual name='visual'>
          <geometry>
            <mesh>
              <scale>10 10 10</scale>
              <uri>model://construction_cone/meshes/construction_cone.dae</uri>
            </mesh>
          </geometry>
        </visual>
        <self_collide>0</self_collide>
        <inertial>
          <pose>0 0 0 0 -0 0</pose>
          <inertia>
            <ixx>1</ixx>
            <ixy>0</ixy>
            <ixz>0</ixz>
            <iyy>1</iyy>
            <iyz>0</iyz>
            <izz>1</izz>
          </inertia>
          <mass>1</mass>
        </inertial>
        <enable_wind>0</enable_wind>
        <kinematic>0</kinematic>
      </link>
      <pose>-5.5648 0.238086 0 0 -0 0</pose>
    </model>
  </world>
</sdf>
