<robot name="tree_mobile">
  <link name="base_link">
    <inertial>
      <origin xyz="0.010085 -7.8763E-06 -0.0066048" rpy="0 0 0" />
      <mass value="0.12" />
      <inertia ixx="0.0001" ixy="0" ixz="0" iyy="0.0003" iyz="0" izz="0.0002" />
    </inertial>
    <visual>
      <origin xyz="0 0 0" rpy="0 0 0" />
      <geometry>
        <mesh filename="package://robot_mobile/meshes/base_link.STL" />
      </geometry>
      <material name="">
        <color rgba="1 1 1 0.3" />
      </material>
    </visual>
    <collision>
      <origin xyz="0 0 0" rpy="0 0 0" />
      <geometry>
        <mesh filename="package://robot_mobile/meshes/base_link.STL" />
      </geometry>
    </collision>
  </link>

  <gazebo reference="base_link">
    <mu1>200</mu1>
    <mu2>200</mu2>
    <kp>1000000</kp>
    <kd>1</kd>
    <material>Gazebo/Blue</material>
  </gazebo>

  <link name="Rueda_izquierda_link">
    <inertial>
      <origin xyz="8.9146E-10 -3.2512E-08 -0.011873" rpy="0 0 0" />
      <mass value="0.1403" />
      <inertia ixx="0.0001" ixy="0" ixz="0" iyy="0.0003" iyz="0" izz="0.0002" />
    </inertial>
    <visual>
      <origin xyz="0 0 0" rpy="0 0 0" />
      <geometry>
        <mesh filename="package://robot_mobile/meshes/Rueda_izquierda_link.STL" />
      </geometry>
      <material name="">
        <color rgba="0.79216 0.81961 0.93333 1" />
      </material>
    </visual>
    <collision>
      <origin xyz="0 0 0" rpy="0 0 0" />
      <geometry>
        <mesh filename="package://robot_mobile/meshes/Rueda_izquierda_link.STL" />
      </geometry>
    </collision>
  </link>

  <joint name="Rueda_izquierda_joint" type="continuous">
    <origin xyz="-0.033259 0.08025 -0.01375" rpy="-1.5708 0.042481 0" />
    <parent link="base_link" />
    <child link="Rueda_izquierda_link" />
    <axis xyz="0 0 1" />
    <dynamics damping="0.1" friction="0.1" />
  </joint>

  <gazebo reference="Rueda_izquierda_link">
    <mu1>200</mu1>
    <mu2>200</mu2>
    <kp>1000000</kp>
    <kd>1</kd>
    <material>Gazebo/Gray</material>
  </gazebo>

  <link name="Rueda_derecha_link">
    <inertial>
      <origin xyz="-8.9146E-10 -3.2512E-08 0.011873" rpy="0 0 0" />
      <mass value="0.1403" />
      <inertia ixx="0.0001" ixy="0" ixz="0" iyy="0.0003" iyz="0" izz="0.0002" />
    </inertial>
    <visual>
      <origin xyz="0 0 0" rpy="0 0 0" />
      <geometry>
        <mesh filename="package://robot_mobile/meshes/Rueda_derecha_link.STL" />
      </geometry>
      <material name="">
        <color rgba="0.79216 0.81961 0.93333 1" />
      </material>
    </visual>
    <collision>
      <origin xyz="0 0 0" rpy="0 0 0" />
      <geometry>
        <mesh filename="package://robot_mobile/meshes/Rueda_derecha_link.STL" />
      </geometry>
    </collision>
  </link>

  <gazebo reference="Rueda_derecha_link">
    <mu1>200</mu1>
    <mu2>200</mu2>
    <kp>1000000</kp>
    <kd>1</kd>
    <material>Gazebo/Gray</material>
  </gazebo>

  <joint name="Rueda_derecha_joint" type="continuous">
    <origin xyz="-0.033259 -0.08025 -0.01375" rpy="1.5708 0.042481 -3.1416" />
    <parent link="base_link" />
    <child link="Rueda_derecha_link" />
    <axis xyz="0 0 1" />
    <dynamics damping="0.1" friction="0.1" />
  </joint>

  <link name="Base_castor_link">
    <inertial>
      <origin xyz="0 0 0" rpy="0 0 0" />
      <mass value="0.5" />
      <inertia ixx="0.00004" ixy="0" ixz="0" iyy="0.00004" iyz="0" izz="0.00001" />
    </inertial>
    <visual>
      <origin xyz="0 0 0" rpy="0 0 0" />
      <geometry>
        <mesh filename="package://robot_mobile/meshes/Base_castor_link.STL" />
      </geometry>
      <material name="">
        <color rgba="1 1 1 1" />
      </material>
    </visual>
    <collision>
      <origin xyz="0 0 0" rpy="0 0 0" />
      <geometry>
        <mesh filename="package://robot_mobile/meshes/Base_castor_link.STL" />
      </geometry>
    </collision>
  </link>

  <gazebo reference="Base_castor_link">
    <mu1>0.1</mu1>
    <mu2>0.1</mu2>
    <kp>1000000</kp>
    <kd>1</kd>
    <material>Gazebo/Gray</material>
  </gazebo>

  <joint name="Base_castor_joint" type="continuous">
    <origin xyz="0.072581 0 -0.0025" rpy="-3.1408 0 0" />
    <parent link="base_link" />
    <child link="Base_castor_link" />
    <axis xyz="0 0 1" />
  </joint>

  <link name="Rueda_castor_link">
    <inertial>
      <origin xyz="6.93889390390723E-18 -2.62037475051713E-11 -2.77710070911708E-09" rpy="0 0 0" />
      <mass value="0.0828739992319076" />
      <inertia ixx="0.0004" ixy="0" ixz="0" iyy="0.0004" iyz="0" izz="0.00001" />
    </inertial>
    <visual>
      <origin xyz="0 0 0" rpy="0 0 0" />
      <geometry>
        <mesh filename="package://robot_mobile/meshes/Rueda_castor_link.STL" />
      </geometry>
      <material name="">
        <color rgba="1 1 1 1" />
      </material>
    </visual>
    <collision>
      <origin xyz="0 0 0" rpy="0 0 0" />
      <geometry>
        <mesh filename="package://robot_mobile/meshes/Rueda_castor_link.STL" />
      </geometry>
    </collision>
  </link>

  <gazebo reference="Rueda_castor_link">
    <mu1>0.1</mu1>
    <mu2>0.1</mu2>
    <kp>1000000</kp>
    <kd>1</kd>
    <material>Gazebo/Gray</material>
  </gazebo>

  <joint name="Rueda_castor_joint" type="continuous">
    <origin xyz="0.015014 -0.00012272 0.02296" rpy="0 -1.57 1.5708" />
    <parent link="Base_castor_link" />
    <child link="Rueda_castor_link" />
    <axis xyz="0 0 1" />
  </joint>

<link name="top_structure">
  <inertial>
    <origin xyz="0 0 0" rpy="0 0 0" />
    <mass value="0.0001" />
    <inertia ixx="0.0001" ixy="0" ixz="0" iyy="0.0001" iyz="0" izz="0.0001" />
  </inertial>

  <!-- Section visuelle avec le maillage -->
  <visual>
    <origin xyz="0 0 0.008" rpy="0 0 0" />
    <geometry>
      <!-- Remplacez la boîte par le maillage -->
      <mesh filename="package://robot_mobile/meshes/structure.stl" />
    </geometry>
    <material name="">
      <color rgba="0.8 0.8 0.8 1" />
    </material>
  </visual>

  <!-- Section de collision (vous pouvez utiliser une boîte simplifiée ou le même maillage) -->
  <collision>
    <origin xyz="0 0 0.01" rpy="0 0 0" />
    <geometry>
      <!-- Utilisez une boîte simplifiée pour la collision -->
      <box size="0.09 0.09 0.01" />
    </geometry>
  </collision>
</link>

<joint name="structure_joint" type="fixed">
  <origin xyz="0 0 0.01" rpy="0 0 0" />
  <parent link="base_link" />
  <child link="top_structure" />
</joint>


<gazebo reference="top_structure">
  <mu1>0.2</mu1>
  <mu2>0.2</mu2>
  <kp>1000</kp>
  <kd>10</kd>
  <material>Gazebo/Blue</material>
</gazebo>

  <link name="Lidar_link">
    <inertial>
      <origin xyz="0 0 0.0" rpy="0 0 0"/>
      <mass value="0.001"/>
      <inertia ixx="0.0001" ixy="0" ixz="0" iyy="0.0001" iyz="0" izz="0.0001" />
    </inertial>
    <visual>
      <origin xyz="0 0 0" rpy="0 0 0"/>
      <geometry>
        <cylinder radius="0.045" length="0.03"/>
      </geometry>
      <material name="">
        <color rgba="1 1 0 0.5" />
      </material>
    </visual>
    <collision>
      <origin xyz="0 0 0.0" rpy="0 0 0"/>
      <geometry>
        <cylinder radius="0.045" length="0.03"/>
      </geometry>
      <material name="">
        <color rgba="1 1 1 0.5" />
      </material>
    </collision>
  </link>

  <joint name="Lidar_joint" type="fixed">
    <origin xyz="0.0 0 0.03" rpy="0 -0.09 0" />
    <parent link="base_link" />
    <child link="Lidar_link" />
    <axis xyz="1 0 0" />
  </joint>

  <link name="imu_link"/>
  <joint name="imu_joint" type="fixed">
    <origin xyz="0.0 0 0.0" rpy="0 -0.07 0" />
    <parent link="base_link" />
    <child link="imu_link" />
    <axis xyz="1 0 0" />
  </joint>

  <!-- CAMERA -->
  <link name="camera_link">
    <visual>
      <geometry>
        <box size="0.002 0.002 0.002"/>
      </geometry>
    </visual>
  </link>

  <joint name="camera_joint" type="fixed">
    <parent link="base_link"/>
    <child link="camera_link"/>
    <origin xyz="0.085 0 0.029" rpy="0 -0.2 0"/>
  </joint>

  <gazebo reference="camera_link">
    <sensor type="camera" name="camera">
      <update_rate>30.0</update_rate>
      <camera>
        <horizontal_fov>1.047</horizontal_fov>
        <image>
          <width>640</width>
          <height>480</height>
          <format>R8G8B8</format>
        </image>
        <clip>
          <near>0.1</near>
          <far>100.0</far>
        </clip>
      </camera>
      <plugin name="camera_controller" filename="libgazebo_ros_camera.so">
        <ros>
          <namespace>/tree_mobile</namespace>
          <argument>image_raw</argument>
        </ros>
      </plugin>
      <visualize>true</visualize>
    </sensor>
  </gazebo>

  <gazebo reference="Lidar_link">
    <sensor name="lidar" type="ray">
      <always_on>true</always_on>
      <visualize>true</visualize>
      <update_rate>20</update_rate>
      <ray>
        <scan>
          <horizontal>
            <samples>180</samples>
            <resolution>1.000000</resolution>
            <min_angle>-1.57079</min_angle>
            <max_angle>1.57079</max_angle>    
          </horizontal>
        </scan>
        <range>
          <min>0.07</min>
          <max>5.0</max>
          <resolution>0.015</resolution>
        </range>
        <noise>
          <type>gaussian</type>
          <mean>0.0</mean>
          <stddev>0.01</stddev>
        </noise>
      </ray>
      <plugin name="scan" filename="libgazebo_ros_ray_sensor.so">
        <ros>
          <remapping>~/out:=scan</remapping>
        </ros>
        <output_type>sensor_msgs/LaserScan</output_type>
        <frame_name>Lidar_link</frame_name>
      </plugin>
    </sensor>
  </gazebo>

  <gazebo reference="Lidar_link">
    <mu1>0.1</mu1>
    <mu2>0.1</mu2>
    <kp>1000000</kp>
    <kd>1</kd>
    <material>Gazebo/Blue</material>
  </gazebo>

  <gazebo reference="imu_link">
    <gravity>true</gravity>
    <sensor name="imu_sensor" type="imu">
      <always_on>true</always_on>
      <update_rate>100</update_rate>
      <visualize>true</visualize>
      <topic>imu_data</topic>
      <imu>
        <angular_velocity>
          <noise>
            <type>gaussian</type>
            <mean>0.0</mean>
            <stddev>0.01</stddev>
          </noise>
        </angular_velocity>
        <linear_acceleration>
          <noise>
            <type>gaussian</type>
            <mean>0.0</mean>
            <stddev>0.02</stddev>
          </noise>
        </linear_acceleration>
      </imu>
    </sensor>
  </gazebo>

  <gazebo>
    <plugin name="two_wheeled_robot_diff_drive" filename="libgazebo_ros_diff_drive.so">
      <update_rate>100</update_rate>
      <left_joint>Rueda_izquierda_joint</left_joint>
      <right_joint>Rueda_derecha_joint</right_joint>
      <wheel_separation>0.15</wheel_separation>
      <wheel_diameter>0.06</wheel_diameter>
      <max_wheel_torque>20</max_wheel_torque>
      <max_wheel_acceleration>2.0</max_wheel_acceleration>
      <command_topic>cmd_vel</command_topic>
      <publish_odom>true</publish_odom>
      <publish_odom_tf>true</publish_odom_tf>
      <publish_wheel_tf>false</publish_wheel_tf>
      <odometry_topic>odom</odometry_topic>
      <odometry_frame>odom</odometry_frame>
      <robot_base_frame>base_link</robot_base_frame>
      <odometry_source>1</odometry_source>
      <ros>
        <remapping>~/out:=joint_states</remapping>
      </ros>
    </plugin>
  </gazebo>

  <gazebo>
    <plugin name="gazebo_ros_joint_state_publisher" filename="libgazebo_ros_joint_state_publisher.so">
      <update_rate>100</update_rate>
      <joint_name>Base_castor_joint</joint_name>
      <joint_name>Rueda_castor_joint</joint_name>
    </plugin>
  </gazebo>
  <gazebo>
    <plugin name="gazebo_ros2_control" filename="libgazebo_ros2_control.so">
        <robot_namespace>/</robot_namespace>
    </plugin>
</gazebo>
  
</robot>

